Workbook

Sheet Dashboard
B1: IELTSPath — Project Tracking Dashboard
B2: Auto-summary from all tracking sheets · Update data in individual sheets
B4: Total Deliverables | C4: Done / Closed | D4: In Progress | E4: Not Started | F4: Open Issues | G4: Open Defects
B5: =COUNTA(Scope!$B$5:$B$44) -> 32 | C5: =COUNTIF(Scope!$G$5:$G$44,"Done")+COUNTIF(Scope!$G$5:$G$44,"Completed")+COUNTIF(Scope!$G$5:$G$44,"Closed") -> 8 | D5: =COUNTIF(Scope!$G$5:$G$44,"In Progress") -> 0 | E5: =COUNTIF(Scope!$G$5:$G$44,"Not Started") -> 24 | F5: =COUNTIF(Issues!$K$5:$K$13,"Open") -> 9 | G5: =COUNTIF(Defects!$N$5:$N$12,"Pending")+COUNTIF(Defects!$N$5:$N$12,"Open") -> 3
B7: Open Issues | C7: Open Defects | D7: Unanswered Q&As | E7: High/Critical Risks
B8: =F5 -> 9 | C8: =G5 -> 3 | D8: =COUNTIF('Q&A'!$K$5:$K$19,"Open") -> 8 | E8: =COUNTIF(Risks!$F$5:$F$15,">=4") -> 10
B11: Scope Milestone Status
B12: Stage | C12: Key Deliverable | D12: Deadline | E12: In Charge | F12: Status
B13: Stage 1 | C13: Report 1 (Project Introduction) | D13: Week 1 | E13: =IF(Scope!C6="","",Scope!C6) -> PhuPD | F13: =IF(COUNTIF(Scope!$G$6:$G$6,"Done")+COUNTIF(Scope!$G$6:$G$6,"Completed")=COUNTA(Scope!$B$6:$B$6),"Done",IF(COUNTIF(Scope!$G$6:$G$6,"Blocked")>0,"Blocked",IF(COUNTIF(Scope!$G$6:$G$6,"Not Started")=COUNTA(Scope!$B$6:$B$6),"Not Started","In Progress"))) -> Done
B14: Stage 2 | C14: SRS v0.9 + Project Management Plan | D14: Week 3 | E14: =IF(Scope!C9="","",Scope!C9) -> All team | F14: =IF(COUNTIF(Scope!$G$8:$G$10,"Done")+COUNTIF(Scope!$G$8:$G$10,"Completed")=COUNTA(Scope!$B$8:$B$10),"Done",IF(COUNTIF(Scope!$G$8:$G$10,"Blocked")>0,"Blocked",IF(COUNTIF(Scope!$G$8:$G$10,"Not Started")=COUNTA(Scope!$B$8:$B$10),"Not Started","In Progress"))) -> Done
B15: Stage 3 | C15: SDS v1.0 + Test Planning | D15: Week 5 | E15: =IF(Scope!C13="","",Scope!C13) -> All team | F15: =IF(COUNTIF(Scope!$G$12:$G$15,"Done")+COUNTIF(Scope!$G$12:$G$15,"Completed")=COUNTA(Scope!$B$12:$B$15),"Done",IF(COUNTIF(Scope!$G$12:$G$15,"Blocked")>0,"Blocked",IF(COUNTIF(Scope!$G$12:$G$15,"Not Started")=COUNTA(Scope!$B$12:$B$15),"Not Started","In Progress"))) -> Done
B16: Stage 4 | C16: Implementation Iterations 1–3 | D16: Week 11 | E16: =IF(Scope!C17="","",Scope!C17) | F16: =IF(COUNTIF(Scope!$G$17:$G$36,"Done")+COUNTIF(Scope!$G$17:$G$36,"Completed")=COUNTA(Scope!$B$17:$B$36),"Done",IF(COUNTIF(Scope!$G$17:$G$36,"Blocked")>0,"Blocked",IF(COUNTIF(Scope!$G$17:$G$36,"Not Started")=COUNTA(Scope!$B$17:$B$36),"Not Started","In Progress"))) -> Not Started
B17: Stage 5 | C17: System Test Report + User Guides + UAT | D17: Week 13 | E17: =IF(Scope!C38="","",Scope!C38) | F17: =IF(COUNTIF(Scope!$G$38:$G$41,"Done")+COUNTIF(Scope!$G$38:$G$41,"Completed")=COUNTA(Scope!$B$38:$B$41),"Done",IF(COUNTIF(Scope!$G$38:$G$41,"Blocked")>0,"Blocked",IF(COUNTIF(Scope!$G$38:$G$41,"Not Started")=COUNTA(Scope!$B$38:$B$41),"Not Started","In Progress"))) -> Not Started
B18: Stage 6 | C18: Final Report + Presentation | D18: Week 14 | E18: =IF(Scope!C43="","",Scope!C43) | F18: =IF(COUNTIF(Scope!$G$43:$G$44,"Done")+COUNTIF(Scope!$G$43:$G$44,"Completed")=COUNTA(Scope!$B$43:$B$44),"Done",IF(COUNTIF(Scope!$G$43:$G$44,"Blocked")>0,"Blocked",IF(COUNTIF(Scope!$G$43:$G$44,"Not Started")=COUNTA(Scope!$B$43:$B$44),"Not Started","In Progress"))) -> Not Started
B20: WBS by Iteration
B21: Iteration | C21: Planned Functions | D21: Est. Effort (pts) | E21: Done | F21: In Progress | G21: % Complete
B22: Iteration 1 | C22: =COUNTIF(WBS!$H$5:$H$86,B22) -> 39 | D22: =SUMIF(WBS!$H$5:$H$86,B22,WBS!$G$5:$G$86) -> 224 | E22: =COUNTIFS(WBS!$H$5:$H$86,B22,WBS!$K$5:$K$86,"Done") -> 22 | F22: =COUNTIFS(WBS!$H$5:$H$86,B22,WBS!$K$5:$K$86,"In Progress") -> 17 | G22: =IF(C22=0,"n.a.",E22/C22*100) -> 56.410256
B23: Iteration 2 | C23: =COUNTIF(WBS!$H$5:$H$86,B23) -> 18 | D23: =SUMIF(WBS!$H$5:$H$86,B23,WBS!$G$5:$G$86) -> 94 | E23: =COUNTIFS(WBS!$H$5:$H$86,B23,WBS!$K$5:$K$86,"Done") -> 0 | F23: =COUNTIFS(WBS!$H$5:$H$86,B23,WBS!$K$5:$K$86,"In Progress") -> 7 | G23: =IF(C23=0,"n.a.",E23/C23*100) -> 0
B24: Iteration 3 | C24: =COUNTIF(WBS!$H$5:$H$86,B24) -> 25 | D24: =SUMIF(WBS!$H$5:$H$86,B24,WBS!$G$5:$G$86) -> 133 | E24: =COUNTIFS(WBS!$H$5:$H$86,B24,WBS!$K$5:$K$86,"Done") -> 0 | F24: =COUNTIFS(WBS!$H$5:$H$86,B24,WBS!$K$5:$K$86,"In Progress") -> 0 | G24: =IF(C24=0,"n.a.",E24/C24*100) -> 0
B27: Last updated: 09/10/2026 | Project: English Learning and IELTS Preparation Support System Based on Personalized Learning Pathways for IELTS Space | PM: LinhNDM

Sheet Scope
A1: Scope — Project Deliverables & Milestones
A2: Track all deliverables by stage · Update Status and Actual Effort each week · % Complete auto-calculated
A4: # | B4: Work Package / Deliverable | C4: In Charge | D4: Est. Effort (pds) | E4: Deadline | F4: % Complete | G4: Status | H4: Actual Effort (pds) | I4: Dependency | J4: Approved By | K4: Notes
A5: Stage 1: Project Initiating (Week 1)
A6: 1.1 | B6: Report 1 — Project Introduction | C6: PhuPD | D6: 2 | E6: Week 1 | F6: =IFERROR(H6/D6*100,"") -> 100 | G6: Done | H6: 2 | J6: LinhNDM
A7: Stage 2: Project Planning & Initial Requirements (Weeks 2–3)
A8: 2.1 | B8: Report 2 — Project Management Plan v1.0 | C8: PhuPD, HieuLT, TungVPH | D8: 3 | E8: Week 2 | F8: =IFERROR(H8/D8*100,"") -> 100 | G8: Done | H8: 3 | I8: 1.1, 2.1 | J8: LinhNDM | K8: Planning, roles, timeline, risk, communication, tracking
A9: 2.2 | B9: Report 3 — SRS v0.9 (Overall Requirements) | C9: All team | D9: 4 | E9: Week 3 | F9: =IFERROR(H9/D9*100,"") -> 100 | G9: Done | H9: 4 | I9: 1.1 | J9: LinhNDM | K9: Scope, actors, functional requirements finalized
A10: 2.3 | B10: Vertical Prototypes (Code Demo) | C10: BE + FE | D10: 5 | E10: Week 3 | F10: =IFERROR(H10/D10*100,"") -> 100 | G10: Done | H10: 5 | I10: 2.1 | J10: LinhNDM | K10: Demonstrate a small end-to-end flow to prove the stack works.
A11: Stage 3: Software Design (Weeks 4–5)
A12: 3.1 | B12: Vertical Prototypes (POC / Proof of Concepts) | C12: BE + FE | D12: 4 | E12: Week 4 | F12: =IFERROR(H12/D12*100,"") -> 100 | G12: Done | H12: 4 | I12: 2.2 | J12: LinhNDM | K12: Develop a Proof of Concept (POC) for technical components that involve risk or uncertainty.
A13: 3.2 | B13: Report 3 — SRS v1.0 (Detailed — Iteration 1) | C13: All team | D13: 4 | E13: Week 4 | F13: =IFERROR(H13/D13*100,"") -> 100 | G13: Done | H13: 4 | I13: 2.1, 3.2 | J13: LinhNDM | K13: Detailed requirements for features to be implemented in Iteration 1
A14: 3.3 | B14: Report 4 — SDS v1.0 (High Level Design) | C14: PhuPD, HieuLT, TungVPH | D14: 5 | E14: Week 5 | F14: =IFERROR(H14/D14*100,"") -> 100 | G14: Done | H14: 5 | I14: 2.1, 2.2 | J14: LinhNDM | K14: Architecture, service/module, DB high-level, API/interface, deployment overview
A15: 3.4 | B15: Report 5 — Test Planning | C15: PhuPD | D15: 3 | E15: Week 5 | F15: =IFERROR(H15/D15*100,"") -> 100 | G15: Done | H15: 3 | I15: 2.1, 3.2 | J15: LinhNDM | K15: Test strategy, test types, environment, entry/exit criteria, responsibilities
A16: Stage 4a: Implementation — Iteration 1 (Weeks 6–7)
A17: 4.1.1 | B17: Report 4 — SDS v1.1 (Detailed Design) | E17: Week 6 | F17: =IFERROR(H17/D17*100,"") | G17: Not Started
A18: 4.1.2 | B18: Code Package & Unit Testing Report — Iteration 1 | E18: Week 6 | F18: =IFERROR(H18/D18*100,"") | G18: Not Started
A19: 4.1.3 | B19: Report 5 — Integration Test Cases — Iteration 1 | E19: Week 6 | F19: =IFERROR(H19/D19*100,"") | G19: Not Started
A20: 4.1.4 | B20: Report 5 — Integration Test Report — Iteration 1 | E20: Week 7 | F20: =IFERROR(H20/D20*100,"") | G20: Not Started
A21: 4.1.5 | B21: Report 3 — SRS v1.1 (Detailed — Iteration 2) | E21: Week 7 | F21: =IFERROR(H21/D21*100,"") | G21: Not Started
A22: 4.1.6 | B22: Software Package Version 1 | E22: Week 7 | F22: =IFERROR(H22/D22*100,"") | G22: Not Started
A23: Stage 4b: Implementation — Iteration 2 (Weeks 8–9)
A24: 4.2.1 | B24: Report 4 — SDS v1.2 | E24: Week 8 | F24: =IFERROR(H24/D24*100,"") | G24: Not Started
A25: 4.2.2 | B25: Code Package & Unit Testing Report — Iteration 2 | E25: Week 8 | F25: =IFERROR(H25/D25*100,"") | G25: Not Started
A26: 4.2.3 | B26: Report 5 — Integration Test Cases — Iteration 2 | E26: Week 8 | F26: =IFERROR(H26/D26*100,"") | G26: Not Started
A27: 4.2.4 | B27: Report 5 — Integration Test Report — Iteration 2 | E27: Week 9 | F27: =IFERROR(H27/D27*100,"") | G27: Not Started
A28: 4.2.5 | B28: Report 3 — SRS v1.2 (Detailed — Iteration 3) | E28: Week 9 | F28: =IFERROR(H28/D28*100,"") | G28: Not Started
A29: 4.2.6 | B29: Software Package Version 2 | E29: Week 9 | F29: =IFERROR(H29/D29*100,"") | G29: Not Started
A30: Stage 4c: Implementation — Iteration 3 (Weeks 10–11)
A31: 4.3.1 | B31: Report 4 — SDS v1.3 | E31: Week 10 | F31: =IFERROR(H31/D31*100,"") | G31: Not Started
A32: 4.3.2 | B32: Code Package & Unit Testing Report — Iteration 3 | E32: Week 10 | F32: =IFERROR(H32/D32*100,"") | G32: Not Started
A33: 4.3.3 | B33: Report 5 — Integration Test Cases — Iteration 3 | E33: Week 10 | F33: =IFERROR(H33/D33*100,"") | G33: Not Started
A34: 4.3.4 | B34: Report 5 — Integration Test Report — Iteration 3 | E34: Week 11 | F34: =IFERROR(H34/D34*100,"") | G34: Not Started
A35: 4.3.5 | B35: Report 5 — System Test Cases | E35: Week 11 | F35: =IFERROR(H35/D35*100,"") | G35: Not Started
A36: 4.3.6 | B36: Software Package Version 3 | E36: Week 11 | F36: =IFERROR(H36/D36*100,"") | G36: Not Started
A37: Stage 5: Verification & Validation (Weeks 12–13)
A38: 5.1 | B38: Report 5 — System Test Report | E38: Week 12 | F38: =IFERROR(H38/D38*100,"") | G38: Not Started
A39: 5.2 | B39: Report 6 — User Guides (Installation + User Manuals) | E39: Week 12 | F39: =IFERROR(H39/D39*100,"") | G39: Not Started
A40: 5.3 | B40: Acceptance Test and Support | E40: Week 13 | F40: =IFERROR(H40/D40*100,"") | G40: Not Started
A41: 5.4 | B41: Final Software Package (Docs + Source Codes) | E41: Week 13 | F41: =IFERROR(H41/D41*100,"") | G41: Not Started
...

Sheet WBS
A1: IELTSPath — Work Breakdown Structure
A2: Complexity: Simple (≤7 fields / ≤3 tx) · Medium (≤15 / ≤7) · Complex (>15 / >7) · Effort: Simple=3 / Medium=5 / Complex=8 pts (default)
A4: Function / Screen | B4: Type | C4: Feature Group | D4: Sub-Feature | E4: Description | F4: Complexity | G4: Est. Effort (pts) | H4: Planned Iteration | I4: In Charge | J4: Actual Effort (pts) | K4: Status | L4: Notes
A5: WBS-001 — Home | B5: Screen | C5: Public / Access | D5: FT-10, FT-11, FT-12 | E5: Introduces IELTSPath, shows the FREE / Premium plans and point cards, and lets a signed-in learner redeem an activation key for Premium days or points. Route: /home · Public page (default route for guests) | F5: Simple | G5: 3 | H5: Iteration 1 | I5: HoangNV | K5: In Progress | L5: FDS §2.1; FT-10, FT-11, FT-12; UC-30, UC-26; FE: partly built; Specified (key activation not wired in the frontend: GAP-03). Role: Guest and any signed-in user. Done means implemented screen scope, not formal UAT approval. | Initial proposed window 2026-09-29 to 2026-10-07; completion depends on WBS-055, WBS-056, WBS-068. Remaining scope carries into Iteration 2, target 21/10/2026. Owner/window/points are reconstructed planning assumptions. Actual points unknown; blank is not zero.
A6: WBS-002 — Login | B6: Screen | C6: Authentication | D6: FT-02, FT-03, FT-05, FT-07 | E6: Lets a registered user sign in with email and password, so the app can return to the page the user wanted or open the learning path. Route: /login · Public page (GuestOnly) | F6: Medium | G6: 5 | H6: Iteration 1 | I6: HoangNV | K6: In Progress | L6: FDS §2.2; FT-02, FT-03, FT-05, FT-07; UC-02, UC-03; FE: built, real API; Specified (OAuth button: Draft; role-based home: GAP-02). Role: Guest. Done means implemented screen scope, not formal UAT approval. | Initial proposed window 2026-09-29 to 2026-10-07; completion depends on WBS-055, WBS-056, WBS-069. Remaining scope carries into Iteration 2, target 21/10/2026. Owner/window/points are reconstructed planning assumptions. Actual points unknown; blank is not zero.
A7: WBS-003 — Register | B7: Screen | C7: Authentication | D7: FT-01, FT-02 | E7: Lets a guest create a learner account and signs the guest in straight away, so learning can start. Route: /register · Public page (GuestOnly) | F7: Simple | G7: 3 | H7: Iteration 1 | I7: HoangNV | K7: Done | L7: FDS §2.3; FT-01, FT-02; UC-01; FE: built, real API; Specified. Role: Guest. Done means implemented screen scope, not formal UAT approval. | Initial proposed window 2026-10-02 to 2026-10-07; completion depends on WBS-055, WBS-056, WBS-069. Owner/window/points are reconstructed planning assumptions. Actual points unknown; blank is not zero.
A8: WBS-004 — Forgot Password | B8: Screen | C8: Authentication | D8: FT-04 | E8: Lets a user who forgot the password ask for a reset code, so a new password can be set. Route: /forgot-password · Public page (GuestOnly) | F8: Simple | G8: 3 | H8: Iteration 1 | I8: HoangNV | K8: In Progress | L8: FDS §2.4; FT-04; UC-04, UC-05; FE: built, real API; Specified (email delivery: Draft, GAP-06). Role: Guest. Done means implemented screen scope, not formal UAT approval. | Initial proposed window 2026-09-29 to 2026-10-07; completion depends on WBS-055, WBS-069. Remaining scope carries into Iteration 2, target 21/10/2026. Owner/window/points are reconstructed planning assumptions. Actual points unknown; blank is not zero.
A9: WBS-005 — Reset Password | B9: Screen | C9: Authentication | D9: FT-04 | E9: Lets the user set a new password with the reset code, so the user can sign in again. Route: /reset-password?token=… · Public page (GuestOnly) | F9: Simple | G9: 3 | H9: Iteration 1 | I9: HoangNV | K9: In Progress | L9: FDS §2.5; FT-04; UC-04; FE: built, real API; Specified (link delivery: Draft, GAP-06). Role: Guest. Done means implemented screen scope, not formal UAT approval. | Initial proposed window 2026-09-29 to 2026-10-07; completion depends on WBS-004, WBS-069. Remaining scope carries into Iteration 2, target 21/10/2026. Owner/window/points are reconstructed planning assumptions. Actual points unknown; blank is not zero.
A10: WBS-006 — OAuth Callback | B10: Screen | C10: Authentication | D10: FT-05 | E10: Finishes a sign-in with the OAuth identity provider and opens the learning path. Route: /auth/oauth/callback · Public page (GuestOnly) | F10: Simple | G10: 3 | H10: Iteration 3 | I10: HoangNV | K10: Not Started | L10: FDS §2.6; FT-05; UC-03; FE: placeholder route; Draft. Role: Guest. | Initial proposed window 2026-10-29 to 2026-12-09; completion depends on WBS-069. Owner/window/points are reconstructed planning assumptions. Actual points unknown; blank is not zero.
A11: WBS-007 — Overview | B11: Screen | C11: Prototype | D11: FT-26, FT-44, FT-45 (intended) | E11: Gives the learner a dashboard of study time, four-skill progress, words to review, mentor feedback, courses and the study streak. Route: /overview · RequireAuth (default route when signed in) | F11: Simple | G11: 3 | H11: Iteration 2 | I11: SonLT | K11: In Progress | L11: FDS §2.7; FT-26, FT-44, FT-45 (intended); UC-19, UC-18; FE: built on mock data; Draft (UI on mock data, OQ-17). Role: Any signed-in user. Mock UI exists; product implementation is incomplete. | Initial proposed window 2026-10-08 to 2026-10-28; completion depends on WBS-057, WBS-071, WBS-076. Owner/window/points are reconstructed planning assumptions. Actual points unknown; blank is not zero.
A12: WBS-008 — Learning Path | B12: Screen | C12: Core Learning | D12: FT-13, FT-20, FT-28 | E12: Display the learning path and ordered topics within a chosen course. Course chooser/recommendation and course-final-test UI are WBS-073; shared contract mappings are WBS-075. Route: /learn. | F12: Simple | G12: 3 | H12: Iteration 1 | I12: HoangNV | K12: In Progress | L12: FDS §2.8; FT-13, FT-20, FT-28; UC-08; FE: built, real API; Specified (skill grouping: GAP-01; Premium lock: Draft). Role: Signed-in learner. Done means implemented screen scope, not formal UAT approval. | Initial proposed window 2026-09-29 to 2026-10-07; completion depends on WBS-055, WBS-056, WBS-070, WBS-072, WBS-073. Remaining scope carries into Iteration 2, target 21/10/2026. Owner/window/points are reconstructed planning assumptions. Actual points unknown; blank is not zero.
A13: WBS-009 — Topic Detail | B13: Screen | C13: Core Learning | D13: FT-20, FT-21, FT-27, FT-29 | E13: Lists the ordered lessons of a topic and the final test card, so the learner can open the next lesson, go to practice or start the final test. Route: /learn/topics/:topicId · RequireAuth | F13: Medium | G13: 5 | H13: Iteration 1 | I13: HoangNV | K13: In Progress | L13: FDS §2.9; FT-20, FT-21, FT-27, FT-29; UC-08, UC-20; FE: built, real API; Specified. Role: Signed-in learner. Done means implemented screen scope, not formal UAT approval. New 07/10 course/multi-skill DTO and gate changes still need FE alignment and fresh browser verification; old FDS acceptance scope is incomplete. | Initial proposed window 2026-09-29 to 2026-10-07; completion depends on WBS-008, WBS-066, WBS-070, WBS-075. Remaining scope carries into Iteration 2, target 21/10/2026. Owner/window/points are reconstructed planning assumptions. Actual points unknown; blank is not zero.
A14: WBS-010 — Lesson Player | B14: Screen | C14: Core Learning | D14: FT-21, FT-22, FT-23, FT-24, FT-25 | E14: Presents a lesson's blocks in order — text, passage, audio, exercises and essays — grades each exercise block, so the learner can pass the lesson and move on. Route: /learn/lessons/:lessonId · RequireAuth | F14: Medium | G14: 5 | H14: Iteration 1 | I14: HoangNV | K14: In Progress | L14: FDS §2.10; FT-21, FT-22, FT-23, FT-24, FT-25; UC-09, UC-12, UC-13; FE: built, real API; Specified. Role: Signed-in learner. Done means implemented screen scope, not formal UAT approval. New 07/10 course/multi-skill DTO and gate changes still need FE alignment and fresh browser verification; old FDS acceptance scope is incomplete. | Initial proposed window 2026-09-29 to 2026-10-07; completion depends on WBS-009, WBS-066, WBS-070, WBS-074, WBS-075. Remaining scope carries into Iteration 2, target 21/10/2026. Owner/window/points are reconstructed planning assumptions. Actual points unknown; blank is not zero.
A15: WBS-011 — Writing Feedback | B15: Screen | C15: Core Learning | D15: FT-12, FT-25 | E15: Shows the AI grading of a Writing essay — estimated band, pass or not, criteria, corrections and the sample answer — so the learner can improve the next essay. Route: Inline panel in /learn/lessons/:lessonId (EssayBlock) | F15: Simple | G15: 3 | H15: Iteration 1 | I15: HoangNV | K15: In Progress | L15: FDS §2.11; FT-12, FT-25; UC-12, UC-13, UC-27; FE: partly built; Specified (separate page and re-reading a submission: GAP-08). Role: Signed-in learner. Done means implemented screen scope, not formal UAT approval. | Initial proposed window 2026-09-29 to 2026-10-07; completion depends on WBS-010, WBS-057, WBS-068, WBS-075. Remaining scope carries into Iteration 2, target 21/10/2026. Owner/window/points are reconstructed planning assumptions. Actual points unknown; blank is not zero.
A16: WBS-012 — Practice Set | B16: Screen | C16: Core Learning | D16: FT-23, FT-24, FT-26, FT-27 | E16: Lists the practice sets of a completed lesson and lets the learner answer one set, see every solution and start the review it creates. Route: /learn/lessons/:lessonId/practice · RequireAuth | F16: Simple | G16: 3 | H16: Iteration 1 | I16: HoangNV | K16: In Progress | L16: FDS §2.12; FT-23, FT-24, FT-26, FT-27; UC-10; FE: built, real API; Specified (Premium sets disabled: GAP-05). Role: Signed-in learner. Done means implemented screen scope, not formal UAT approval. New 07/10 course/multi-skill DTO and gate changes still need FE alignment and fresh browser verification; old FDS acceptance scope is incomplete. | Initial proposed window 2026-09-29 to 2026-10-07; completion depends on WBS-010, WBS-057, WBS-074, WBS-075. Remaining scope carries into Iteration 2, target 21/10/2026. Owner/window/points are reconstructed planning assumptions. Actual points unknown; blank is not zero.
... A86: WBS-082 — Notification service scaffold | B86: Non-UI | C86: Notification | D86: FT-51, FT-52, FT-53, FT-54 | E86: Create the service module and shared configuration/routing baseline only; notification delivery, reminders and retries remain future scope. | F86: Medium | G86: 5 | H86: Iteration 1 | I86: TungVPH | K86: Done | L86: Git backend 11a78fa6. Done applies only to the narrow initialization package, not a completed user feature. | Initial proposed 2026-09-22 to 2026-09-23; completion depends on WBS-051, WBS-052, WBS-053, WBS-054. Owner/date/points are reconstructed planning assumptions; actual points unknown.
A88: Iteration summary — estimate points; operational acceptance tracked separately
A89: Iteration | B89: Work packages | C89: Estimate points | D89: Done | E89: In Progress | F89: Not Started | G89: Blocked
A90: Iteration 1 | B90: =COUNTIF($H$5:$H$86,A90) -> 39 | C90: =SUMIF($H$5:$H$86,A90,$G$5:$G$86) -> 224 | D90: =COUNTIFS($H$5:$H$86,A90,$K$5:$K$86,"Done") -> 22 | E90: =COUNTIFS($H$5:$H$86,A90,$K$5:$K$86,"In Progress") -> 17 | F90: =COUNTIFS($H$5:$H$86,A90,$K$5:$K$86,"Not Started") -> 0 | G90: =COUNTIFS($H$5:$H$86,A90,$K$5:$K$86,"Blocked") -> 0
A91: Iteration 2 | B91: =COUNTIF($H$5:$H$86,A91) -> 18 | C91: =SUMIF($H$5:$H$86,A91,$G$5:$G$86) -> 94 | D91: =COUNTIFS($H$5:$H$86,A91,$K$5:$K$86,"Done") -> 0 | E91: =COUNTIFS($H$5:$H$86,A91,$K$5:$K$86,"In Progress") -> 7 | F91: =COUNTIFS($H$5:$H$86,A91,$K$5:$K$86,"Not Started") -> 11 | G91: =COUNTIFS($H$5:$H$86,A91,$K$5:$K$86,"Blocked") -> 0
A92: Iteration 3 | B92: =COUNTIF($H$5:$H$86,A92) -> 25 | C92: =SUMIF($H$5:$H$86,A92,$G$5:$G$86) -> 133 | D92: =COUNTIFS($H$5:$H$86,A92,$K$5:$K$86,"Done") -> 0 | E92: =COUNTIFS($H$5:$H$86,A92,$K$5:$K$86,"In Progress") -> 0 | F92: =COUNTIFS($H$5:$H$86,A92,$K$5:$K$86,"Not Started") -> 25 | G92: =COUNTIFS($H$5:$H$86,A92,$K$5:$K$86,"Blocked") -> 0
A93: Total | B93: =SUM(B90:B92) -> 82 | C93: =SUM(C90:C92) -> 451 | D93: =SUM(D90:D92) -> 22 | E93: =SUM(E90:E92) -> 24 | F93: =SUM(F90:F92) -> 36 | G93: =SUM(G90:G92) -> 0
A97: Proposed iteration plan — calendar dates estimated, not an approved schedule
A98: Iteration | B98: Start | C98: Finish | D98: Objective | E98: Entry dependencies | F98: Exit / acceptance | G98: Lead
A99: Iteration 1 | B99: 46274 | C99: 46302 | D99: Requirements → infrastructure → BE core → FE auth/learning → documented smoke. Course/multi-skill BE landed late. | E99: Requirements and service contracts; Content before Learning/Assessment; BE endpoints before FE HTTP. | F99: Implemented scope recorded. Fresh browser, course FE and live providers remain outstanding; iteration date does not imply acceptance. | G99: HieuLT
A100: Iteration 2 | B100: 46303 | C100: 46323 | D100: Align course/multi-skill FE, clear core flow gaps, reconcile docs; integrate priority account/library screens. | E100: Iteration 1 APIs; C-006/C-008 contract reconciliation. | F100: Unassisted browser + course/multi-skill regression evidence, updated RTW/FDS/Test Plan and reviewed findings. | G100: HoangNV
A101: Iteration 3 | B101: 46324 | C101: 46365 | D101: Proposed extended staff, notification, games/community and remaining screens, after prioritization. | E101: Validated core flow and confirmed scope; external providers/data available. | F101: Acceptance by confirmed feature list. Classroom/Speaking/mobile and external integrations need explicit scope decisions. | G101: HieuLT
A105: Team ownership — proposed allocations based on the supplied roles
A106: Member | B106: Role | C106: Primary scope | D106: Coordinates with | E106: Historical attribution | F106: Approval authority | G106: Capacity assumption
A107: PhuPD | B107: BE | C107: User/Auth + Assessment + outbox | D107: HieuLT / HoangNV | E107: PhuPham70 matches PhuPD by supplied name; other assignments inferred. | F107: TimeLog and project approval: LinhNDM (PM / supervisor). | G107: Student project: around 2–4 h/day; no actual timesheets.
A108: HoangNV | B108: FE lead | C108: FE auth, learning, course and multi-skill alignment | D108: SonLT / HieuLT | E108: Nguyen Viet Hoang / hoangnv31 observed in Git. | F108: FE review lead; no historic formal approval invented. | G108: Estimated daily entries capped at 8 h/person.
A109: SonLT | B109: BE + FE | C109: Library/activity follow-up, prototype, FDS and system QA | D109: HoangNV / TungVPH | E109: sonledz22 observed in Git. | F109: Cross-review/testing owner (proposed). | G109: Work dates/hours reconstructed; overlap checked.
A110: HieuLT | B110: Tech lead / task assignment | C110: Architecture, Java Learning, course/multi-skill and coordination | D110: All members | E110: hieuLeFpt / Lê Trung Hiếu observed in Git. | F110: Technical coordination and task allocation; PM / project reviewer: LinhNDM. | G110: AI-authored commits attributed only as proposed human oversight.
A111: TungVPH | B111: BE | C111: Content, Access, infrastructure and operational checks | D111: PhuPD / HieuLT | E111: Git account mapping not confirmed; assignments are proposed. | F111: Backend review/implementation allocation (proposed). | G111: No unsupported historic Git identity asserted.
A112: LinhNDM | B112: PM / project supervisor | C112: Project oversight, review and approval | D112: All team | E112: Confirmed by user | F112: TimeLogs and project review | G112: Supervisor; five-member implementation team unchanged
A115: Basis and interpretation
A116: Item | B116: Value / rule | C116: Source | D116: Version / date | E116: Owner | F116: Status | G116: Limit
A117: Project start | B117: 09/09/2026 | C117: Report 1 Vision & Scope | D117: v1.1.0 / 07/10/2026 | E117: HieuLT | F117: Source date | G117: Earlier than repo creation; planning work can precede Git.
A118: Repo creation | B118: 14/09/2026 | C118: GitHub repository metadata | D118: Backend + Frontend | E118: HieuLT | F118: Source date | G118: First commit is not necessarily first work day.
A119: Snapshot | B119: 07/10/2026 23:59 ICT | C119: BE e24d9eef; FE 3b933051 | D119: Main branches at cutoff | E119: HieuLT | F119: Git evidence | G119: Current later documents are reference only, not dated evidence at cutoff.
...

Sheet Q&A
A1: Q&A — IELTSPath Phase 1
A2: Log ALL questions — technical, business, process · Track from Open → Answered → Closed · Never delete a row
A4: # | B4: Date | C4: Question | D4: Raised By | E4: Directed To | F4: Priority | G4: Due Date | H4: Answer / Resolution | I4: Answered By | J4: Answered Date | K4: Status | L4: Notes
A5: Q-001 | B5: 46302 | C5: What does Phase 1 cover, and how does it relate to WBS Iteration 1? | D5: LinhNDM | E5: HieuLT | F5: High | G5: 46304 | H5: Proposed baseline: Iteration 1 covers 09/09–07/10 foundation/core and BE course/multi-skill. Iteration 2 closes FE contract/E2E gaps; Iteration 3 contains prioritized extensions. See WBS iteration plan. Team must confirm acceptance scope; dates alone do not prove acceptance. | K5: Open | L5: capstone-docs/rp_5.0_test_plan/Report 5.0_TestPlan_IELTSPath_v1.docx; original WBS A5:L17. Review question recorded 07/10/2026; not an earlier meeting minute. | LinhNDM: supervisor asking; Directed To: responsible team member. Answered By is a simulated response assignment based on cited evidence.
A6: Q-002 | B6: 46302 | C6: Who are the Phase 1 users and what problem does IELTSPath address? | D6: LinhNDM | E6: HieuLT | F6: Medium | G6: 46302 | H6: New visitors try the centre teaching before enrolment. Current and waiting-list learners practise between classes and see their own progress. | I6: HieuLT | J6: 46302 | K6: Answered | L6: backend/capstone-docs/rp_1_vision-scope/Report 1_Vision_Scope_IeltsPath.docx §1, §3, §5 | LinhNDM: supervisor asking; Directed To: responsible team member. Answered By is a simulated response assignment based on cited evidence.
A7: Q-003 | B7: 46302 | C7: Which implementation is the current learning backend? | D7: LinhNDM | E7: HieuLT | F7: High | G7: 46302 | H7: Java learning-service owns lesson progress, mastery, review, practice and assessment-result consumption. The former Python AI Learning flow is superseded. | I7: HieuLT | J7: 46302 | K7: Answered | L7: backend/AGENTS.md §1; backend/docs/system-architecture.md | LinhNDM: supervisor asking; Directed To: responsible team member. Answered By is a simulated response assignment based on cited evidence.
A8: Q-004 | B8: 46302 | C8: What authentication and authorization contract must FE follow? | D8: LinhNDM | E8: PhuPD | F8: High | G8: 46302 | H8: Use Gateway APIs, Bearer access token and the existing refresh flow. Gateway validates external JWT and signs an internal JWT. Protected services enforce role and ownership. | I8: PhuPD | J8: 46302 | K8: Answered | L8: backend/docs/fe-main-flow-guide.md §1, §4; frontend/src/lib/httpClient.ts; backend/README.md | LinhNDM: supervisor asking; Directed To: responsible team member. Answered By is a simulated response assignment based on cited evidence.
A9: Q-005 | B9: 46302 | C9: When does a learner unlock a topic test? | D9: LinhNDM | E9: HieuLT | F9: High | G9: 46302 | H9: Core final-test assignment requires all relevant lessons completed, Practice cleared and applicable reviews closed; topic pass requires >=70%. The 07/10 multi-skill BE clears Practice per objective skill; FE must align to updated contracts. | I9: HieuLT | J9: 46302 | K9: Answered | L9: backend/docs/fe-main-flow-guide.md §3–4; frontend/plans/reports/e2e-practice-261005/report.md | LinhNDM: supervisor asking; Directed To: responsible team member. Answered By is a simulated response assignment based on cited evidence.
A10: Q-006 | B10: 46302 | C10: Are live Writing AI grading and points already fully accepted? | D10: LinhNDM | E10: HieuLT | F10: High | G10: 46306 | H10: Lesson essay integration exists: at least 3 points, 3-point charge, request replay and >=60-second FE timeout. Live LLM quality and complete paid retry behaviour need separate acceptance evidence. | K10: Open | L10: backend/docs/fe-main-flow-guide.md; frontend/plans/reports/e2e-practice-261005/report.md; capstone-docs/rp_5.0_test_plan/Report 5.0_TestPlan_IELTSPath_v1.docx TP-LRN-06 | LinhNDM: supervisor asking; Directed To: responsible team member. Answered By is a simulated response assignment based on cited evidence.
A11: Q-007 | B11: 46302 | C11: Is Listening playback ready for the Phase 1 demo? | D11: LinhNDM | E11: TungVPH | F11: High | G11: 46304 | H11: AudioBlock is integrated. Provide valid media and test playback. Transcript must appear only when the backend exposes it after the permitted submission. | K11: Open | L11: backend/docs/fe-main-flow-guide.md; frontend/plans/reports/e2e-practice-261005/report.md; capstone-docs/rp_5.0_test_plan/Report 5.0_TestPlan_IELTSPath_v1.docx | LinhNDM: supervisor asking; Directed To: responsible team member. Answered By is a simulated response assignment based on cited evidence.
A12: Q-008 | B12: 46302 | C12: Does premium activation require online payment? | D12: LinhNDM | E12: TungVPH | F12: Medium | G12: 46302 | H12: No. Sales distribute activation cards outside the system. The system records activations and grants access or points; payment, invoicing and revenue reporting are excluded. | I12: TungVPH | J12: 46302 | K12: Answered | L12: backend/capstone-docs/rp_1_vision-scope/Report 1_Vision_Scope_IeltsPath.docx §4.2 LI-01; backend/capstone-docs/rp_3.0_system-requirements-system/Report 3.0_SRS_IELTSPath_IeltsPath_v1.docx SC-03 | LinhNDM: supervisor asking; Directed To: responsible team member. Answered By is a simulated response assignment based on cited evidence.
A13: Q-009 | B13: 46302 | C13: Is a premium badge sufficient access protection? | D13: LinhNDM | E13: HieuLT | F13: High | G13: 46306 | H13: No. Current MVP has UI flags but no learning subscription enforcement. Decide whether Phase 1 is free-only or must add server-side entitlement before a paid release. | K13: Open | L13: backend/docs/fe-main-flow-guide.md §6; capstone-docs/rp_5.0_test_plan/Report 5.0_TestPlan_IELTSPath_v1.docx Out of Scope | LinhNDM: supervisor asking; Directed To: responsible team member. Answered By is a simulated response assignment based on cited evidence.
A14: Q-010 | B14: 46302 | C14: Can the 05/10 E2E report be described as full browser acceptance? | D14: LinhNDM | E14: SonLT | F14: High | G14: 46302 | H14: No. Fresh registration, test submit and result were exercised in browser. Lessons and Practice used API assistance; review was N/A. Full unassisted UI acceptance is still needed. | I14: SonLT | J14: 46302 | K14: Answered | L14: frontend/plans/reports/e2e-main-flow-261005-fresh/report.md Method and checklist; frontend/plans/reports/e2e-practice-261005/report.md E2E note | LinhNDM: supervisor asking; Directed To: responsible team member. Answered By is a simulated response assignment based on cited evidence.
A15: Q-011 | B15: 46302 | C15: Are band courses and placement recommendation available across BE and FE? | D15: LinhNDM | E15: HoangNV | F15: Medium | G15: 46305 | H15: Backend course work merged on 07/10. FE currently loads topics and has no course methods in LearningApi. Live course smoke and phase inclusion remain open. | K15: Open | L15: backend/plans/261006-2228-course-band-levels/plan.md final verification; frontend/src/features/learning-path/api/learningApi.ts | LinhNDM: supervisor asking; Directed To: responsible team member. Answered By is a simulated response assignment based on cited evidence.
A16: Q-012 | B16: 46302 | C16: Are mixed-skill lessons and free assessment AI essays completed? | D16: LinhNDM | E16: HieuLT | F16: Medium | G16: 46302 | H16: Backend multi-skill implementation merged 07/10 via 8d2d2bb (#47), with phase verification and documented concerns. FE mixed-skill/assessment-essay alignment and live-provider acceptance are not established. See WBS-074/075 and C-008. | I16: HieuLT | J16: 46302 | K16: Answered | L16: BE merge 8d2d2bb; plans/261006-2309-multi-skill-lessons/plan.md verification; FE 3b933051. Supersedes V1 stale Pending claim. | LinhNDM: supervisor asking; Directed To: responsible team member. Answered By is a simulated response assignment based on cited evidence.
A17: Q-013 | B17: 46302 | C17: Should Speaking, full mock tests, mobile, games and community count as Phase 1 accepted features? | D17: LinhNDM | E17: HieuLT | F17: High | G17: 46304 | H17: They are product features in Vision & Scope, but outside the priority test v1 boundary or lack full flow evidence. Confirm future delivery allocation; do not mark accepted from code presence alone. | K17: Open | L17: backend/capstone-docs/rp_1_vision-scope/Report 1_Vision_Scope_IeltsPath.docx §4.1; capstone-docs/rp_5.0_test_plan/Report 5.0_TestPlan_IELTSPath_v1.docx Out of Scope | LinhNDM: supervisor asking; Directed To: responsible team member. Answered By is a simulated response assignment based on cited evidence.
A18: Q-014 | B18: 46302 | C18: What are the official reporters, hours, dates and approvals for timesheets? | D18: LinhNDM | E18: HieuLT | F18: High | G18: 46305 | H18: Five implementation members confirmed. PM and project reviewer are both LinhNDM; HieuLT remains tech lead/task coordinator. TimeLogs contains 48 consecutively numbered entries totaling 211.5 hours. PM identity is confirmed; actual member timesheets and historical approval records still require reconciliation. | K18: Open | L18: Original Scope names PhuPD, HieuLT, TungVPH; no row-level work-hour evidence found. | LinhNDM: supervisor asking; Directed To: responsible team member. Answered By is a simulated response assignment based on cited evidence.
A19: Q-015 | B19: 46302 | C19: Have the updated SRS, TDS and test plan been formally approved? | D19: LinhNDM | E19: HieuLT | F19: High | G19: 46306 | H19: Formal document approval not evidenced. SRS was updated to v0.9.21 on 07/10, while RTW/FDS and the later Test Plan still need course/multi-skill reconciliation. The Test Plan now includes browser system testing; the old mock-only claim is superseded. | K19: Open | L19: backend/capstone-docs/rp_3.0_system-requirements-system/Report 3.0_SRS_IELTSPath_IeltsPath_v1.docx metadata; capstone-docs/rp_5.0_test_plan/Report 5.0_TestPlan_IELTSPath_v1.docx baseline/out-of-scope; frontend/plans/reports/e2e-main-flow-261005-fresh/report.md | LinhNDM: supervisor asking; Directed To: responsible team member. Answered By is a simulated response assignment based on cited evidence.

Sheet TimeLogs
A1: TimeLogs — IELTSPath Phase 1
A2: Log time daily · Link every entry to a WBS Ref · Approved by PM · # Hours must be filled — leave no blank
A4: # | B4: Date | C4: Reporter | D4: WBS Ref | E4: Task Description | F4: Activity | G4: Type | H4: # Hours | I4: Product / Work Product | J4: Iteration | K4: Status | L4: Approved By | M4: Updated | N4: Notes
A5: TL-001 | B5: 46274 | C5: PhuPD | D5: WBS-065 | E5: Project kickoff, initial problem/scope and member task allocation | F5: Meeting | G5: Newly-Created | H5: 1.5 | I5: Initial project plan | J5: Iteration 1 | K5: Approved | L5: LinhNDM | M5: 46304 | N5: Start date: Report 1; participation estimated.
A6: TL-002 | B6: 46274 | C6: HoangNV | D6: WBS-065 | E6: Project kickoff, initial problem/scope and member task allocation | F6: Meeting | G6: Newly-Created | H6: 1.5 | I6: Initial project plan | J6: Iteration 1 | K6: Approved | L6: LinhNDM | M6: 46304 | N6: Start date: Report 1; participation estimated.
A7: TL-003 | B7: 46274 | C7: SonLT | D7: WBS-065 | E7: Project kickoff, initial problem/scope and member task allocation | F7: Meeting | G7: Newly-Created | H7: 1.5 | I7: Initial project plan | J7: Iteration 1 | K7: Approved | L7: LinhNDM | M7: 46304 | N7: Start date: Report 1; participation estimated.
A8: TL-004 | B8: 46274 | C8: HieuLT | D8: WBS-065 | E8: Project kickoff, initial problem/scope and member task allocation | F8: Meeting | G8: Newly-Created | H8: 1.5 | I8: Initial project plan | J8: Iteration 1 | K8: Submitted | M8: 46302 | N8: Start date: Report 1; participation estimated.
A9: TL-005 | B9: 46274 | C9: TungVPH | D9: WBS-065 | E9: Project kickoff, initial problem/scope and member task allocation | F9: Meeting | G9: Newly-Created | H9: 1.5 | I9: Initial project plan | J9: Iteration 1 | K9: Approved | L9: LinhNDM | M9: 46304 | N9: Start date: Report 1; participation estimated.
A10: TL-006 | B10: 46280 | C10: HieuLT | D10: WBS-055 | E10: Initialize React / TypeScript / Vite and application folders | F10: Coding | G10: Newly-Created | H10: 3 | I10: Frontend scaffold | J10: Iteration 1 | K10: Submitted | M10: 46302 | N10: FE 241abca.
A11: TL-007 | B11: 46280 | C11: HieuLT | D11: WBS-055 | E11: Configure Tailwind, shadcn setup, theme and import aliases | F11: Coding | G11: Newly-Created | H11: 2.5 | I11: FE styling foundation | J11: Iteration 1 | K11: Submitted | M11: 46302 | N11: FE 241abca.
A12: TL-008 | B12: 46280 | C12: HieuLT | D12: WBS-055 | E12: Configure Node/npm constraints, dependencies, lint/typecheck/build | F12: Coding | G12: Newly-Created | H12: 2 | I12: FE tooling baseline | J12: Iteration 1 | K12: Submitted | M12: 46302 | N12: FE 241abca, 8581a72.
A13: TL-009 | B13: 46281 | C13: HieuLT | D13: WBS-053 | E13: Implement Gateway routing, external/internal JWT and service security | F13: Coding | G13: Updating | H13: 5 | I13: Ingress and security baseline | J13: Iteration 1 | K13: Submitted | M13: 46302 | N13: BE 218e071, a18a44e.
A14: TL-010 | B14: 46282 | C14: HieuLT | D14: WBS-051 | E14: Initialize Maven multi-module build and service structure | F14: Coding | G14: Newly-Created | H14: 2.5 | I14: Backend scaffold | J14: Iteration 1 | K14: Submitted | M14: 46302 | N14: BE 218e071: Maven multi-module build and backend service structure.
A15: TL-011 | B15: 46282 | C15: TungVPH | D15: WBS-052 | E15: Set up Config Server, configuration repository and Eureka | F15: Coding | G15: Newly-Created | H15: 3.5 | I15: Service infrastructure | J15: Iteration 1 | K15: Approved | L15: LinhNDM | M15: 46304 | N15: BE 218e071.
A16: TL-012 | B16: 46282 | C16: TungVPH | D16: WBS-054 | E16: Set up Docker Compose, PostgreSQL and container configuration | F16: Coding | G16: Updating | H16: 4 | I16: Local infrastructure setup | J16: Iteration 1 | K16: Approved | L16: LinhNDM | M16: 46304 | N16: BE 218e071, dac8b03.
A17: TL-013 | B17: 46282 | C17: PhuPD | D17: WBS-069 | E17: Initialize User service module, configuration and account/auth structure | F17: Coding | G17: Newly-Created | H17: 1.5 | I17: User service initialization | J17: Iteration 1 | K17: Approved | L17: LinhNDM | M17: 46304 | N17: BE 218e071: User service initialization; auth updates and tests recorded separately.
A18: TL-014 | B18: 46287 | C18: PhuPD | D18: WBS-069 | E18: Add user unit tests and HttpOnly-cookie authentication | F18: Coding | G18: Updating | H18: 6.5 | I18: User/auth APIs and tests | J18: Iteration 1 | K18: Approved | L18: LinhNDM | M18: 46304 | N18: BE 115c36d, 2c9d37f.
A19: TL-015 | B19: 46287 | C19: TungVPH | D19: WBS-082 | E19: Scaffold Notification service and register shared configuration/routing | F19: Coding | G19: Newly-Created | H19: 1.5 | I19: Notification service scaffold/config | J19: Iteration 1 | K19: Approved | L19: LinhNDM | M19: 46304 | N19: BE 11a78fa6: Notification scaffold/configuration/routing; delivery, reminders and retry remain outstanding.
A20: TL-016 | B20: 46288 | C20: TungVPH | D20: WBS-066 | E20: Initialize Content service, Flyway schema and base content APIs | F20: Coding | G20: Updating | H20: 3 | I20: Content service baseline | J20: Iteration 1 | K20: Approved | L20: LinhNDM | M20: 46304 | N20: BE 11a78fa: Content module, schema and base APIs.
A21: TL-017 | B21: 46288 | C21: SonLT | D21: WBS-079 | E21: Build mock learning workspace and UI prototype | F21: Coding | G21: Updating | H21: 6 | I21: Initial learning UI | J21: Iteration 1 | K21: Approved | L21: LinhNDM | M21: 46304 | N21: FE 6ffb8a4, b8d3f3f.
A22: TL-018 | B22: 46288 | C22: PhuPD | D22: WBS-068 | E22: Initialize Access service, plans/points APIs and Access tests | F22: Coding | G22: Newly-Created | H22: 2.5 | I22: Access service baseline | J22: Iteration 1 | K22: Approved | L22: LinhNDM | M22: 46304 | N22: BE 99b7d4f / 3678274: Access service initialization and tests.
A23: TL-019 | B23: 46288 | C23: TungVPH | D23: WBS-081 | E23: Initialize Community service and initial community backend code | F23: Coding | G23: Newly-Created | H23: 3 | I23: Community service initial module/code | J23: Iteration 1 | K23: Approved | L23: LinhNDM | M23: 46304 | N23: BE 559718a4 / 10433389: initial Community module/code; complete community flows remain outstanding.
A24: TL-020 | B24: 46288 | C24: HoangNV | D24: WBS-071 | E24: Initialize historical Learning Support service before Library/activity migration | F24: Coding | G24: Newly-Created | H24: 1.5 | I24: Historical Learning Support module | J24: Iteration 1 | K24: Approved | L24: LinhNDM | M24: 46304 | N24: BE 3512cc8f / b886d3f2: historical Learning Support module, later replaced by Library/activity migration.
A25: TL-021 | B25: 46289 | C25: PhuPD | D25: WBS-067 | E25: Initialize Assessment service and attempt/answer domain structure | F25: Coding | G25: Updating | H25: 3.5 | I25: Assessment service baseline | J25: Iteration 1 | K25: Approved | L25: LinhNDM | M25: 46304 | N25: BE c087a3f: Assessment module and attempt/answer structure.
A26: TL-022 | B26: 46289 | C26: HieuLT | D26: WBS-070 | E26: Build the historical Python AI Learning prototype and local runtime | F26: Coding | G26: Updating | H26: 4 | I26: Earlier learning prototype | J26: Iteration 1 | K26: Submitted | M26: 46302 | N26: BE e1cf196, f430f61, 4ba99a5, 2860664.
A27: TL-023 | B27: 46289 | C27: PhuPD | D27: WBS-080 | E27: Initialize Game service and initial game backend code | F27: Coding | G27: Newly-Created | H27: 3 | I27: Game service initial module/code | J27: Iteration 1 | K27: Approved | L27: LinhNDM | M27: 46304 | N27: BE c12541b6 / c2561e23: initial Game module/code; full gameplay remains outstanding.
A28: TL-024 | B28: 46294 | C28: SonLT | D28: WBS-079 | E28: Record learning page and interactive-tool verification | F28: Testing | G28: Reviewing | H28: 3.5 | I28: UI verification work | J28: Iteration 1 | K28: Approved | L28: LinhNDM | M28: 46304 | N28: FE 43f537b.
A29: TL-025 | B29: 46294 | C29: HieuLT | D29: WBS-076 | E29: Record backend MVP end-to-end acceptance evidence | F29: Testing | G29: Reviewing | H29: 4 | I29: Backend E2E report | J29: Iteration 1 | K29: Submitted | M29: 46302 | N29: BE 9140128.
A30: TL-026 | B30: 46295 | C30: SonLT | D30: WBS-079 | E30: Add shared UI utilities, learning pages and interactive workspaces | F30: Coding | G30: Updating | H30: 8 | I30: FE pages and UI components | J30: Iteration 1 | K30: Approved | L30: LinhNDM | M30: 46304 | N30: FE 015701d, b93604b.
A31: TL-027 | B31: 46295 | C31: HieuLT | D31: WBS-059 | E31: Implement AssessmentCompleted consumer and update learning progress, review/test assignments | F31: Coding | G31: Updating | H31: 8 | I31: Learning result consumer / progress updates | J31: Iteration 1 | K31: Submitted | M31: 46302 | N31: BE 72d4e99 / dd109f5: result consumer, progress and review/test assignment updates.
A32: TL-028 | B32: 46295 | C32: TungVPH | D32: WBS-066 | E32: Seed Writing, Listening and Reading-hint learning content | F32: Coding | G32: Updating | H32: 5 | I32: Published demo curriculum | J32: Iteration 1 | K32: Approved | L32: LinhNDM | M32: 46304 | N32: BE 37a330c, 555ab81, a163b6b, 70f17a2.
A33: TL-029 | B33: 46296 | C33: SonLT | D33: WBS-071 | E33: Initialize Library service; migrate activity/streak into User and remove legacy Learning Support | F33: Coding | G33: Updating | H33: 6 | I33: Library initialization / service migration | J33: Iteration 1 | K33: Approved | L33: LinhNDM | M33: 46304 | N33: BE 465f543, d762660, fec5d14, ab613b1.
A34: TL-030 | B34: 46296 | C34: TungVPH | D34: WBS-066 | E34: Implement lesson content endpoints and learner answer-redaction guard | F34: Coding | G34: Updating | H34: 5 | I34: Content lesson APIs / security | J34: Iteration 1 | K34: Approved | L34: LinhNDM | M34: 46304 | N34: BE 34335aa, 20bed3b.
A35: TL-031 | B35: 46296 | C35: HieuLT | D35: WBS-070 | E35: Initialize Java Learning service and implement lesson/mastery persistence | F35: Coding | G35: Updating | H35: 8 | I35: Java learning runtime | J35: Iteration 1 | K35: Submitted | M35: 46302 | N35: BE d96ab9e, 8195982.
A36: TL-032 | B36: 46297 | C36: HieuLT | D36: WBS-070 | E36: Implement lesson essay grading, Listening media contract and hint visibility | F36: Coding | G36: Updating | H36: 8 | I36: Writing / Listening / Reading APIs | J36: Iteration 1 | K36: Submitted | M36: 46302 | N36: BE d08337a, 896fa2c, 60c72dd.
A37: TL-033 | B37: 46297 | C37: HoangNV | D37: WBS-056 | E37: Connect frontend main flow to backend and correct submission behaviour | F37: Coding | G37: Updating | H37: 8 | I37: HTTP auth and learning flow | J37: Iteration 1 | K37: Approved | L37: LinhNDM | M37: 46304 | N37: FE 5505282, f1d5bb0.
A38: TL-034 | B38: 46298 | C38: HieuLT | D38: WBS-057 | E38: Implement skill-local progress, required Practice and remediation ladder | F38: Coding | G38: Updating | H38: 8 | I38: Practice / review rules | J38: Iteration 1 | K38: Submitted | M38: 46302 | N38: BE a3447b9, a90e5e1, 853ab82, 1a96c77, 8bb72cf, 6d9f623.
A39: TL-035 | B39: 46298 | C39: HoangNV | D39: WBS-076 | E39: Document browser core-flow checks and API-assisted fresh-user E2E | F39: Testing | G39: Reviewing | H39: 4.5 | I39: FE E2E reports | J39: Iteration 1 | K39: Approved | L39: LinhNDM | M39: 46304 | N39: FE caaf987, 6716dd9.
A40: TL-036 | B40: 46299 | C40: HoangNV | D40: WBS-012 | E40: Fix assessment question snapshot parsing and integrate Practice/review UI | F40: Coding | G40: Bug-Fix | H40: 8 | I40: Test runner / Practice / Review UI | J40: Iteration 1 | K40: Approved | L40: LinhNDM | M40: 46304 | N40: FE d2b737d, 6716dd9.
A41: TL-037 | B41: 46299 | C41: HieuLT | D41: WBS-065 | E41: Complete requirements/data/NFR sections and record scope/BA review | F41: Analyzing | G41: Updating | H41: 5.5 | I41: Requirements and review reports | J41: Iteration 1 | K41: Submitted | M41: 46302 | N41: BE b2323f1 / f2e00d4 / 36b1092: requirements sections and BA/scope review.
...

Sheet Defects
A1: Defects — IELTSPath Phase 1
A2: Log ALL defects found in any review or test · Severity: Critical / High / Medium / Low · Status: Pending → Open → Fixed → Closed
A4: # | B4: Date Found | C4: Defect Description | D4: Steps to Reproduce | E4: Expected Result | F4: Actual Result | G4: Severity | H4: Priority | I4: Activity | J4: Product | K4: Product Details | L4: Assigned By | M4: Assigned To | N4: Status | O4: Fixed Date | P4: Fixed In Version | Q4: Updated | R4: Notes
A5: D-001 | B5: 46300 | C5: Topic lesson mapper omitted practiceStatus | D5: Complete lessons while Practice is REQUIRED; open topic. | E5: Show remaining Practice gate and a clear next action. | F5: Gate state was dropped from mapped lessons. | G5: High | H5: High | I5: System Test | J5: Frontend | K5: Topic mapper and final-test checklist | L5: HieuLT | M5: HoangNV | N5: Fixed | O5: 46300 | P5: FE 6716dd9 (main 3b933051) | Q5: 46302 | R5: frontend/plans/reports/e2e-main-flow-261005/fix-ux-cta-gates.md; frontend/plans/reports/e2e-practice-261005/report.md confirms gap closed; full fresh browser retest still open. | Assignment proposed from team roles; not a historical signed assignment. Fixed indicates documented code fix; separate browser retest required, not Closed.
A6: D-002 | B6: 46300 | C6: PRACTICE_REQUIRED error lacked actionable handling | D6: Try to assign a test while Practice is required. | E6: Explain remaining Practice, show lesson links, reload state. | F6: Generic locked message did not explain Practice requirement. | G6: High | H6: High | I6: System Test | J6: Frontend | K6: Assignment error handling | L6: HieuLT | M6: HoangNV | N6: Fixed | O6: 46300 | P6: FE 6716dd9 (main 3b933051) | Q6: 46302 | R6: frontend/plans/reports/e2e-main-flow-261005/fix-ux-cta-gates.md; frontend/plans/reports/e2e-practice-261005/report.md | Assignment proposed from team roles; not a historical signed assignment. Fixed indicates documented code fix; separate browser retest required, not Closed.
A7: D-003 | B7: 46300 | C7: Pending reviews were not hydrated in topic view | D7: Open a topic with pending review. | E7: Load reviews, display review checklist, hide locked test CTA. | F7: Learner could not see why the final test was locked. | G7: High | H7: High | I7: System Test | J7: Frontend | K7: Topic ReviewGate / GET reviews | L7: HieuLT | M7: HoangNV | N7: Fixed | O7: 46300 | P7: FE 6716dd9 (main 3b933051) | Q7: 46302 | R7: frontend/plans/reports/e2e-main-flow-261005/fix-ux-cta-gates.md; frontend/plans/reports/e2e-practice-261005/report.md browser smoke only. | Assignment proposed from team roles; not a historical signed assignment. Fixed indicates documented code fix; separate browser retest required, not Closed.
A8: D-004 | B8: 46300 | C8: Primary CTA click reliability requires fresh retest | D8: Use accessibility-ref click on login or test CTA. | E8: Accessible activation consistently reaches the button handler. | F8: Automation sometimes missed; Enter or JS click completed the action. | G8: Medium | H8: Medium | I8: System Test | J8: Frontend | K8: Auth and learning primary CTA | L8: HieuLT | M8: HoangNV | N8: Pending | Q8: 46302 | R8: frontend/plans/reports/e2e-main-flow-261005/fix-ux-cta-gates.md records layout fix, but frontend/plans/reports/e2e-main-flow-261005-fresh/report.md repeats observation. Application-wide reproduction is not established. | Assignment proposed from team roles; not a historical signed assignment. Verification concern retained; not a confirmed universal product failure.
A9: D-005 | B9: 46300 | C9: Assessment result accessibility snapshot omitted visible score details | D9: Inspect result page accessibility tree after submit. | E9: Score percent and correct-answer count are perceivable by assistive technology. | F9: Interactive snapshot lacked percent/count despite visible UI text. | G9: Medium | H9: Medium | I9: System Test | J9: Frontend | K9: Result summary accessibility | L9: HieuLT | M9: HoangNV | N9: Pending | Q9: 46302 | R9: frontend/plans/reports/e2e-main-flow-261005/report.md item 5. Verify with a screen reader before confirming defect. | Assignment proposed from team roles; not a historical signed assignment.
A10: D-006 | B10: 46302 | C10: Dashboard open-item formulas used incorrect status columns | D10: Populate Q&A, Defects and Issues statuses; inspect Dashboard formulas. | E10: Count Issues K, Defects N and Q&A K; risk priority from score F | F10: Corrected Dashboard uses the actual status columns and includes risks with score >=4. | G10: Medium | H10: High | I10: Review | J10: Tracking workbook | K10: Dashboard D8, G5/C8 and F5/B8 | L10: HieuLT | M10: HieuLT | N10: Fixed | O10: 46304 | P10: Report 2.1 Dashboard update — 09/10/2026 | Q10: 46304 | R10: Formulas recalculated and checked against source records. Awaiting LinhNDM review; not Closed.
A11: D-007 | B11: 46302 | C11: Dashboard iteration formulas excluded WBS rows after row 68 | D11: Compare WBS headers with Dashboard iteration COUNTIF/SUMIF formulas. | E11: Count all 82 WBS packages through row 86 | F11: Dashboard now uses WBS H for iteration, G for points and K for status across rows 5:86. | G11: Medium | H11: Medium | I11: Review | J11: Tracking workbook | K11: Dashboard iteration table B27:J31; WBS summary A88:G93 | L11: HieuLT | M11: HieuLT | N11: Fixed | O11: 46304 | P11: Report 2.1 Dashboard update — 09/10/2026 | Q11: 46304 | R11: Full WBS range recalculated and reconciled with WBS summary. Awaiting LinhNDM review; not Closed.
A12: D-008 | B12: 46302 | C12: Scope completion percentage still represents effort usage | D12: Compare Scope headers and formulas with Dashboard deliverable counts. | E12: Count statuses in Scope G and treat effort usage separately from completion. | F12: Dashboard counts Scope G correctly. Scope F remains actual/estimated effort, which is not a completion measure. | G12: Medium | H12: Medium | I12: Review | J12: Tracking workbook | K12: Scope F and Dashboard B5:E5 | L12: HieuLT | M12: HieuLT | N12: Open | Q12: 46304 | R12: Dashboard deliverable counts repaired; remaining Scope F interpretation needs separate correction. Defect stays Open.

Sheet Issues
A1: Issues — IELTSPath Phase 1
A2: Issues = problems that have already occurred · Risks = problems that might occur (see Risks sheet) · Category: Technical / Process / Resource / Scope / External
A4: # | B4: Date | C4: Issue Description | D4: Category | E4: Priority | F4: Impact (Scope / Effort / Timeline) | G4: Raised By | H4: Owner | I4: Due Date | J4: Resolution | K4: Status | L4: Closed Date | M4: Notes
A5: I-001 | B5: 46302 | C5: Phase 1 boundary is not explicitly baselined against WBS. | D5: Scope | E5: High | F5: Acceptance and phase reporting may use different feature populations. | G5: HieuLT | H5: HieuLT | I5: 46307 | J5: Confirm reconstructed WBS iteration windows, product acceptance list and extension priorities. See WBS plan, Q-001. Creating the plan does not supply formal acceptance. | K5: Open | M5: capstone-docs/rp_5.0_test_plan/Report 5.0_TestPlan_IELTSPath_v1.docx; original WBS | Owner/deadline are proposed resolution assignments.
A6: I-002 | B6: 46302 | C6: Actual member hours and approved timesheets were not supplied. | D6: Process | E6: High | F6: Approved actual effort and productivity cannot be calculated. | G6: HieuLT | H6: HieuLT | I6: 46307 | J6: Validate the 48-row, 211.5-hour retrospective timesheet against member records, dates, hours and approval evidence. Review states are Pending, Submitted and Approved. See Q-014. | K6: Open | M6: Original tracking workbook contains unrelated sample hours and reporter. | Owner/deadline are proposed resolution assignments.
A7: I-003 | B7: 46302 | C7: Full fresh-user browser Practice/review/pass-to-next-topic flow lacks evidence. | D7: Technical | E7: High | F7: Core MVP acceptance has an unverified UI segment. | G7: HieuLT | H7: SonLT | I7: 46307 | J7: Run without API gate clearance: lesson, first Practice submit, failed Practice review, pass test, next topic. Capture artifacts. | K7: Open | M7: frontend/plans/reports/e2e-main-flow-261005-fresh/report.md; frontend/plans/reports/e2e-practice-261005/report.md | Owner/deadline are proposed resolution assignments.
A8: I-004 | B8: 46302 | C8: Live Writing feedback quality and Listening media acceptance are unverified. | D8: Technical | E8: High | F8: Writing quality and audio demo readiness cannot be concluded from UI/API wiring. | G8: HieuLT | H8: TungVPH | I8: 46311 | J8: Review real essays against rubric and play configured audio; verify timeout, points retry and transcript visibility. | K8: Open | M8: capstone-docs/rp_5.0_test_plan/Report 5.0_TestPlan_IELTSPath_v1.docx; frontend/plans/reports/e2e-practice-261005/report.md | Owner/deadline are proposed resolution assignments.
A9: I-005 | B9: 46302 | C9: SRS v0.9.21 course/multi-skill updates are not synchronized into RTW/FDS and Test Plan. | D9: Process | E9: High | F9: Specifications, permission/feature traceability and tests can target different gates and feature populations. | G9: HieuLT | H9: SonLT | I9: 46311 | J9: Update FT-15/20/55, course/placement flow, BR-35..40, mixed-skill rules and assessment essay fallback; reconcile RTW/FDS/Test Plan. The latest Test Plan includes HTTP/browser tests; old mock-only finding withdrawn. | K9: Open | M9: BE 29810100 / de62b4eb; plans/reports/srs-to-rtw-fds-handoff-261007-1934-course-multi-skill-report.md. Later Test Plan reference still lists 54 features and one-skill assumptions; no completed reconciliation asserted.
A10: I-006 | B10: 46302 | C10: Premium enforcement is absent in the current learning MVP. | D10: Scope | E10: High | F10: Paid content cannot be accepted as protected solely by FE labels. | G10: HieuLT | H10: HieuLT | I10: 46311 | J10: Confirm free-only demo scope or implement entitlement checks as an approved follow-up before paid release. | K10: Open | M10: backend/docs/fe-main-flow-guide.md §6; capstone-docs/rp_5.0_test_plan/Report 5.0_TestPlan_IELTSPath_v1.docx | Owner/deadline are proposed resolution assignments.
A11: I-007 | B11: 46302 | C11: New course/multi-skill BE contracts are not aligned with FE course APIs and full browser acceptance. | D11: Technical | E11: Medium | F11: End-to-end course recommendation and course-test completion remain incomplete. | G11: HieuLT | H11: HoangNV | I11: 46316 | J11: Complete WBS-073/075 after WBS-072/074; verify course selection, mixed Practice, essay gate submission, result processing and next topic. Fresh unassisted browser evidence required. | K11: Open | M11: backend/plans/261006-2228-course-band-levels/plan.md final concerns; frontend/src/features/learning-path/api/learningApi.ts | Owner/deadline are proposed resolution assignments.
A12: I-008 | B12: 46302 | C12: SRS/TDS metadata and formal approval records remain incomplete. | D12: Process | E12: Medium | F12: Cannot substantiate a formally approved requirement/design baseline. | G12: HieuLT | H12: HieuLT | I12: 46311 | J12: Fill authors, reviewers, dates and approval references; reconcile Report 1, SRS and implementation. | K12: Open | M12: backend/capstone-docs/rp_3.0_system-requirements-system/Report 3.0_SRS_IELTSPath_IeltsPath_v1.docx metadata; backend/capstone-docs/rp_1_vision-scope/Report 1_Vision_Scope_IeltsPath.docx In Review; original Scope Approved By is not approval evidence. | Owner/deadline are proposed resolution assignments.
