Workbook

Sheet Dashboard
B1: [Project Name] — Project Tracking Dashboard
B2: Auto-summary from all tracking sheets · Update data in individual sheets
B4: Total Deliverables | C4: Done / Closed | D4: In Progress | E4: Not Started | F4: Open Issues | G4: Open Defects
B5: =COUNTA(Scope!B5:B200)-COUNTBLANK(Scope!B5:B200) -> -132 | C5: =COUNTIF(Scope!F5:F200,"Done")+COUNTIF(Scope!F5:F200,"Completed") -> 0 | D5: =COUNTIF(Scope!F5:F200,"In Progress") -> 0 | E5: =COUNTIF(Scope!F5:F200,"Not Started")+COUNTBLANK(Scope!F5:F200)-1 -> 187 | F5: =COUNTIF(Issues!H5:H200,"Open") -> 0 | G5: =COUNTIF(Defects!H5:H200,"Open")+COUNTIF(Defects!H5:H200,"Pending") -> 0
B7: Open Issues | C7: Open Defects | D7: Unanswered Q&As | E7: High/Critical Risks
B8: =COUNTIF(Issues!H5:H200,"Open") -> 0 | C8: =COUNTIF(Defects!H5:H200,"Open")+COUNTIF(Defects!H5:H200,"Pending") -> 0 | D8: =COUNTIF('Q&A'!G5:G200,"Open") -> 0 | E8: =COUNTIF(Risks!D5:D200,"High")+COUNTIF(Risks!D5:D200,"Critical") -> 0
B11: Scope Milestone Status
B12: Stage | C12: Key Deliverable | D12: Deadline | E12: In Charge | F12: Status
B13: Stage 1 | C13: Report 1 (Project Introduction) | D13: Week 1
B14: Stage 2 | C14: SRS v0.9 + Project Management Plan | D14: Week 3
B15: Stage 3 | C15: SDS v1.0 + Test Planning | D15: Week 5
B16: Stage 4 | C16: Implementation Iterations 1–3 | D16: Week 11
B17: Stage 5 | C17: System Test Report + User Guides + UAT | D17: Week 13
B18: Stage 6 | C18: Final Report + Presentation | D18: Week 14
B20: WBS by Iteration
B21: Iteration | C21: Planned Functions | D21: Est. Effort (pts) | E21: Done | F21: In Progress | G21: % Complete
B22: Iteration 1 | C22: =COUNTIF(WBS!G5:G200,"Iteration 1") -> 0 | D22: =SUMIF(WBS!G5:G200,"Iteration 1",WBS!F5:F200) -> 0 | E22: =COUNTIFS(WBS!G5:G200,"Iteration 1",WBS!H5:H200,"Done") -> 0 | F22: =COUNTIFS(WBS!G5:G200,"Iteration 1",WBS!H5:H200,"In Progress") -> 0
B23: Iteration 2 | C23: =COUNTIF(WBS!G5:G200,"Iteration 2") -> 0 | D23: =SUMIF(WBS!G5:G200,"Iteration 2",WBS!F5:F200) -> 0 | E23: =COUNTIFS(WBS!G5:G200,"Iteration 2",WBS!H5:H200,"Done") -> 0 | F23: =COUNTIFS(WBS!G5:G200,"Iteration 2",WBS!H5:H200,"In Progress") -> 0
B24: Iteration 3 | C24: =COUNTIF(WBS!G5:G200,"Iteration 3") -> 0 | D24: =SUMIF(WBS!G5:G200,"Iteration 3",WBS!F5:F200) -> 0 | E24: =COUNTIFS(WBS!G5:G200,"Iteration 3",WBS!H5:H200,"Done") -> 0 | F24: =COUNTIFS(WBS!G5:G200,"Iteration 3",WBS!H5:H200,"In Progress") -> 0
B27: Last updated: [DD/MM/YYYY] | Project: [Project Name] | PM: [Name]

Sheet Scope
A1: Scope — Project Deliverables & Milestones
A2: Track all deliverables by stage · Update Status and Actual Effort each week · % Complete auto-calculated
A4: # | B4: Work Package / Deliverable | C4: In Charge | D4: Est. Effort (pds) | E4: Deadline | F4: % Complete | G4: Status | H4: Actual Effort (pds) | I4: Dependency | J4: Approved By | K4: Notes
A5: Stage 1: Project Initiating (Week 1)
A6: 1.1 | B6: Report 1 — Project Introduction | C6: PhuPD | D6: 2 | E6: Week 1 | F6: =IFERROR(H6/D6*100,"") -> 100 | G6: Done | H6: 2 | J6: Lecturer
A7: Stage 2: Project Planning & Initial Requirements (Weeks 2–3)
A8: 2.1 | B8: Report 2 — Project Management Plan v1.0 | C8: PhuPD, HieuLT, TungVPH | D8: 3 | E8: Week 2 | F8: =IFERROR(H8/D8*100,"") -> 100 | G8: Done | H8: 3 | I8: 1.1, 2.1 | J8: Lecturer | K8: Planning, roles, timeline, risk, communication, tracking
A9: 2.2 | B9: Report 3 — SRS v0.9 (Overall Requirements) | C9: All team | D9: 4 | E9: Week 3 | F9: =IFERROR(H9/D9*100,"") -> 100 | G9: Done | H9: 4 | I9: 1.1 | J9: Lecturer | K9: Scope, actors, functional requirements finalized
A10: 2.3 | B10: Vertical Prototypes (Code Demo) | C10: BE + FE | D10: 5 | E10: Week 3 | F10: =IFERROR(H10/D10*100,"") -> 100 | G10: Done | H10: 5 | I10: 2.1 | J10: Lecturer | K10: Demonstrate a small end-to-end flow to prove the stack works.
A11: Stage 3: Software Design (Weeks 4–5)
A12: 3.1 | B12: Vertical Prototypes (POC / Proof of Concepts) | C12: BE + FE | D12: 4 | E12: Week 4 | F12: =IFERROR(H12/D12*100,"") -> 100 | G12: Done | H12: 4 | I12: 2.2 | J12: Lecturer | K12: Develop a Proof of Concept (POC) for technical components that involve risk or uncertainty.
A13: 3.2 | B13: Report 3 — SRS v1.0 (Detailed — Iteration 1) | C13: All team | D13: 4 | E13: Week 4 | F13: =IFERROR(H13/D13*100,"") -> 100 | G13: Done | H13: 4 | I13: 2.1, 3.2 | J13: Lecturer | K13: Detailed requirements for features to be implemented in Iteration 1
A14: 3.3 | B14: Report 4 — SDS v1.0 (High Level Design) | C14: PhuPD, HieuLT, TungVPH | D14: 5 | E14: Week 5 | F14: =IFERROR(H14/D14*100,"") -> 100 | G14: Done | H14: 5 | I14: 2.1, 2.2 | J14: Lecturer | K14: Architecture, service/module, DB high-level, API/interface, deployment overview
A15: 3.4 | B15: Report 5 — Test Planning | C15: PhuPD | D15: 3 | E15: Week 5 | F15: =IFERROR(H15/D15*100,"") -> 100 | G15: Done | H15: 3 | I15: 2.1, 3.2 | J15: Lecturer | K15: Test strategy, test types, environment, entry/exit criteria, responsibilities
A16: Stage 4a: Implementation — Iteration 1 (Weeks 6–7)
A17: 4.1.1 | B17: Report 4 — SDS v1.1 (Detailed Design) | E17: Week 6 | F17: =IFERROR(H17/D17*100,"") | G17: Not Started
A18: 4.1.2 | B18: Code Package & Unit Testing Report — Iteration 1 | E18: Week 6 | F18: =IFERROR(H18/D18*100,"") | G18: Not Started
A19: 4.1.3 | B19: Report 5 — Integration Test Cases — Iteration 1 | E19: Week 6 | F19: =IFERROR(H19/D19*100,"") | G19: Not Started
A20: 4.1.4 | B20: Report 5 — Integration Test Report — Iteration 1 | E20: Week 7 | F20: =IFERROR(H20/D20*100,"") | G20: Not Started
A21: 4.1.5 | B21: Report 3 — SRS v1.1 (Detailed — Iteration 2) | E21: Week 7 | F21: =IFERROR(H21/D21*100,"") | G21: Not Started
A22: 4.1.6 | B22: Software Package Version 1 | E22: Week 7 | F22: =IFERROR(H22/D22*100,"") | G22: Not Started
A23: Stage 4b: Implementation — Iteration 2 (Weeks 8–9)
A24: 4.2.1 | B24: Report 4 — SDS v1.2 | E24: Week 8 | F24: =IFERROR(H24/D24*100,"") | G24: Not Started
A25: 4.2.2 | B25: Code Package & Unit Testing Report — Iteration 2 | E25: Week 8 | F25: =IFERROR(H25/D25*100,"") | G25: Not Started
A26: 4.2.3 | B26: Report 5 — Integration Test Cases — Iteration 2 | E26: Week 8 | F26: =IFERROR(H26/D26*100,"") | G26: Not Started
A27: 4.2.4 | B27: Report 5 — Integration Test Report — Iteration 2 | E27: Week 9 | F27: =IFERROR(H27/D27*100,"") | G27: Not Started
A28: 4.2.5 | B28: Report 3 — SRS v1.2 (Detailed — Iteration 3) | E28: Week 9 | F28: =IFERROR(H28/D28*100,"") | G28: Not Started
A29: 4.2.6 | B29: Software Package Version 2 | E29: Week 9 | F29: =IFERROR(H29/D29*100,"") | G29: Not Started
A30: Stage 4c: Implementation — Iteration 3 (Weeks 10–11)
A31: 4.3.1 | B31: Report 4 — SDS v1.3 | E31: Week 10 | F31: =IFERROR(H31/D31*100,"") | G31: Not Started
A32: 4.3.2 | B32: Code Package & Unit Testing Report — Iteration 3 | E32: Week 10 | F32: =IFERROR(H32/D32*100,"") | G32: Not Started
A33: 4.3.3 | B33: Report 5 — Integration Test Cases — Iteration 3 | E33: Week 10 | F33: =IFERROR(H33/D33*100,"") | G33: Not Started
A34: 4.3.4 | B34: Report 5 — Integration Test Report — Iteration 3 | E34: Week 11 | F34: =IFERROR(H34/D34*100,"") | G34: Not Started
A35: 4.3.5 | B35: Report 5 — System Test Cases | E35: Week 11 | F35: =IFERROR(H35/D35*100,"") | G35: Not Started
A36: 4.3.6 | B36: Software Package Version 3 | E36: Week 11 | F36: =IFERROR(H36/D36*100,"") | G36: Not Started
A37: Stage 5: Verification & Validation (Weeks 12–13)
A38: 5.1 | B38: Report 5 — System Test Report | E38: Week 12 | F38: =IFERROR(H38/D38*100,"") | G38: Not Started
A39: 5.2 | B39: Report 6 — User Guides (Installation + User Manuals) | E39: Week 12 | F39: =IFERROR(H39/D39*100,"") | G39: Not Started
A40: 5.3 | B40: Acceptance Test and Support | E40: Week 13 | F40: =IFERROR(H40/D40*100,"") | G40: Not Started
A41: 5.4 | B41: Final Software Package (Docs + Source Codes) | E41: Week 13 | F41: =IFERROR(H41/D41*100,"") | G41: Not Started
...

Sheet WBS
A1: WBS — Work Breakdown Structure (Function / Screen Level)
A2: Complexity: Simple (≤7 fields / ≤3 tx) · Medium (≤15 / ≤7) · Complex (>15 / >7) · Effort: Simple=3 / Medium=5 / Complex=8 pts (default)
A4: Function / Screen | B4: Type | C4: Feature Group | D4: Sub-Feature | E4: Description | F4: Complexity | G4: Est. Effort (pts) | H4: Planned Iteration | I4: In Charge | J4: Actual Effort (pts) | K4: Status | L4: Notes
A5: Home Page | B5: Non-UI | C5: Common | E5: Landing page / entry point | F5: Medium | G5: 5 | H5: Iteration 2 | K5: Not Started
A6: User Login | B6: Screen | C6: Common | E6: Email + password login with JWT | F6: Simple | G6: 3 | H6: Iteration 1 | K6: Not Started
A7: User Register | B7: Screen | C7: Common | E7: New account registration form | F7: Simple | G7: 3 | H7: Iteration 1 | K7: Not Started
A8: Reset Password | B8: Screen | C8: Common | E8: Email OTP-based password reset flow | F8: Medium | G8: 5 | H8: Iteration 3 | K8: Not Started
A9: User Authorization | B9: Non-UI | C9: Common | E9: Role-based access control (RBAC) | F9: Complex | G9: 8 | H9: Iteration 1 | K9: Not Started
A10: User Profile | B10: Screen | C10: Common | E10: View and edit user profile | F10: Simple | G10: 3 | H10: Iteration 3 | K10: Not Started
A11: Change Password | B11: Screen | C11: Common | E11: Change password from profile | F11: Simple | G11: 3 | H11: Iteration 3 | K11: Not Started
A12: Blog List | B12: Screen | C12: Public | E12: Paginated public blog listing | F12: Medium | G12: 5 | H12: Iteration 2 | K12: Not Started
A13: Blog Details | B13: Screen | C13: Public | E13: Single blog post view with comments | F13: Simple | G13: 3 | H13: Iteration 2 | K13: Not Started
A14: Post List | B14: Screen | C14: Marketing | E14: Marketing posts listing with filters | F14: Medium | G14: 5 | H14: Iteration 1 | K14: Not Started
A15: Post Details | B15: Screen | C15: Marketing | E15: Single marketing post detail view | F15: Medium | G15: 5 | H15: Iteration 1 | K15: Not Started
A16: Users List | B16: Screen | C16: System Admin | E16: Admin: list + search all users | F16: Simple | G16: 3 | H16: Iteration 1 | K16: Not Started
A17: User Details | B17: Screen | C17: System Admin | E17: Admin: view + edit single user record | F17: Simple | G17: 3 | H17: Iteration 1 | K17: Not Started
A20: Iteration Summary
A21: Iteration | B21: Planned Functions | C21: Est. Effort (pts) | D21: Done | E21: In Progress
A22: Iteration 1 | B22: 7 | C22: 30
A23: Iteration 2 | B23: 3 | C23: 13
A24: Iteration 3 | B24: 3 | C24: 11
A25: Grand Total | B25: 13 | C25: 54

Sheet Q&A
A1: Q&A — Project Questions & Answers Log
A2: Log ALL questions — technical, business, process · Track from Open → Answered → Closed · Never delete a row
A4: # | B4: Date | C4: Question | D4: Raised By | E4: Directed To | F4: Priority | G4: Due Date | H4: Answer / Resolution | I4: Answered By | J4: Answered Date | K4: Status | L4: Notes
A5: Q-001 | B5: 2024-01-08 | C5: [Describe the question clearly — what needs clarification?] | D5: KienNT | E5: [Assignee/Stakeholder] | F5: Medium | G5: 2024-01-15 | H5: [Answer provided here] | K5: Open
A6: Q-002 | F6: Medium | K6: Open
A7: Q-003 | F7: Medium | K7: Open
A8: Q-004 | F8: Medium | K8: Open
A9: Q-005 | F9: Medium | K9: Open
A10: Q-006 | F10: Medium | K10: Open
A11: Q-007 | F11: Medium | K11: Open
A12: Q-008 | F12: Medium | K12: Open
A13: Q-009 | F13: Medium | K13: Open
A14: Q-010 | F14: Medium | K14: Open
A15: Q-011 | F15: Medium | K15: Open
A16: Q-012 | F16: Medium | K16: Open
A17: Q-013 | F17: Medium | K17: Open
... A24: Q-020 | F24: Medium | K24: Open

Sheet TimeLogs
A1: TimeLogs — Project Timesheets
A2: Log time daily · Link every entry to a WBS Ref · Approved by PM · # Hours must be filled — leave no blank
A4: # | B4: Date | C4: Reporter | D4: WBS Ref | E4: Task Description | F4: Activity | G4: Type | H4: # Hours | I4: Product / Work Product | J4: Iteration | K4: Status | L4: Approved By | M4: Updated | N4: Notes
A5: TL-001 | B5: 2024-10-13 | C5: KienNT | D5: WBS-1 | E5: Set up project repository and CI pipeline | F5: Coding | G5: Newly-Created | H5: 2 | I5: Software Package | J5: Iteration 1 | K5: Submitted | M5: 2024-10-26
A6: TL-002 | C6: KienNT | D6: WBS-2 | E6: Implement user login API with JWT | F6: Coding | G6: Newly-Created | H6: 4 | I6: Software Package | J6: Iteration 1 | K6: Submitted
A7: TL-003 | K7: Submitted
A8: TL-004 | K8: Submitted
A9: TL-005 | K9: Submitted
A10: TL-006 | K10: Submitted
A11: TL-007 | K11: Submitted
A12: TL-008 | K12: Submitted
A13: TL-009 | K13: Submitted
A14: TL-010 | K14: Submitted
A15: TL-011 | K15: Submitted
A16: TL-012 | K16: Submitted
A17: TL-013 | K17: Submitted
A18: TL-014 | K18: Submitted
... A35: TL-031 | K35: Submitted
A39: Hours Summary
A40: Activity | B40: Total Hours
A41: Training | B41: =SUMIF(F5:F500,"Training",H5:H500) -> 0
A42: Analyzing | B42: =SUMIF(F5:F500,"Analyzing",H5:H500) -> 0
A43: Designing | B43: =SUMIF(F5:F500,"Designing",H5:H500) -> 0
A44: Coding | B44: =SUMIF(F5:F500,"Coding",H5:H500) -> 6
A45: Testing | B45: =SUMIF(F5:F500,"Testing",H5:H500) -> 0
A46: Reviewing | B46: =SUMIF(F5:F500,"Reviewing",H5:H500) -> 0
A47: Deploying | B47: =SUMIF(F5:F500,"Deploying",H5:H500) -> 0
A48: Meeting | B48: =SUMIF(F5:F500,"Meeting",H5:H500) -> 0
A49: Grand Total | B49: =SUM(H5:H500) -> 6

Sheet Defects
A1: Defects — Bug & Defect Tracking Log
A2: Log ALL defects found in any review or test · Severity: Critical / High / Medium / Low · Status: Pending → Open → Fixed → Closed
A4: # | B4: Date Found | C4: Defect Description | D4: Steps to Reproduce | E4: Expected Result | F4: Actual Result | G4: Severity | H4: Priority | I4: Activity | J4: Product | K4: Product Details | L4: Assigned By | M4: Assigned To | N4: Status | O4: Fixed Date | P4: Fixed In Version | Q4: Updated | R4: Notes
A5: D-001 | B5: 2024-10-13 | C5: [Describe the defect clearly] | D5: [Step 1: ... Step 2: ...] | E5: [What should happen] | F5: [What actually happened] | G5: Medium | H5: Medium | I5: Review | J5: Software Package | L5: KienNT | M5: [Assignee] | N5: Pending | Q5: 2024-10-26
A6: D-002 | G6: Medium | H6: Medium | N6: Pending
A7: D-003 | G7: Medium | H7: Medium | N7: Pending
A8: D-004 | G8: Medium | H8: Medium | N8: Pending
A9: D-005 | G9: Medium | H9: Medium | N9: Pending
A10: D-006 | G10: Medium | H10: Medium | N10: Pending
A11: D-007 | G11: Medium | H11: Medium | N11: Pending
A12: D-008 | G12: Medium | H12: Medium | N12: Pending
A13: D-009 | G13: Medium | H13: Medium | N13: Pending
A14: D-010 | G14: Medium | H14: Medium | N14: Pending
A15: D-011 | G15: Medium | H15: Medium | N15: Pending
A16: D-012 | G16: Medium | H16: Medium | N16: Pending
A17: D-013 | G17: Medium | H17: Medium | N17: Pending
... A34: D-030 | G34: Medium | H34: Medium | N34: Pending

Sheet Issues
A1: Issues — Project Issues & Risk Events Log
A2: Issues = problems that have already occurred · Risks = problems that might occur (see Risks sheet) · Category: Technical / Process / Resource / Scope / External
A4: # | B4: Date | C4: Issue Description | D4: Category | E4: Priority | F4: Impact (Scope / Effort / Timeline) | G4: Raised By | H4: Owner | I4: Due Date | J4: Resolution | K4: Status | L4: Closed Date | M4: Notes
A5: I-001 | B5: 2024-10-13 | C5: [Describe the issue — what happened and what is the impact?] | D5: Technical | E5: Medium | F5: [Impact on scope / effort / timeline — e.g. delays Iteration 2 by 3 days] | G5: KienNT | H5: HuyNMG | J5: [Resolution steps taken or planned] | K5: Open
A6: I-002 | E6: Medium | K6: Open
A7: I-003 | E7: Medium | K7: Open
A8: I-004 | E8: Medium | K8: Open
A9: I-005 | E9: Medium | K9: Open
A10: I-006 | E10: Medium | K10: Open
A11: I-007 | E11: Medium | K11: Open
A12: I-008 | E12: Medium | K12: Open
A13: I-009 | E13: Medium | K13: Open
A14: I-010 | E14: Medium | K14: Open
A15: I-011 | E15: Medium | K15: Open
A16: I-012 | E16: Medium | K16: Open
A17: I-013 | E17: Medium | K17: Open
... A24: I-020 | E24: Medium | K24: Open

Sheet Risks
A1: Risks — Risk Register & Mitigation Tracking
A2: Probability: High(3) / Medium(2) / Low(1) · Impact: High(3) / Medium(2) / Low(1) · Risk Score = P × I · Score ≥ 6 = Critical; 4-5 = High; 2-3 = Medium; 1 = Low
A4: # | B4: Risk Description | C4: Category | D4: Probability | E4: Impact | F4: Risk Score (P×I) | G4: Mitigation Plan | H4: Contingency Plan | I4: Owner | J4: Due Date | K4: Status | L4: Notes
A5: R-001 | B5: Channel API approval (Facebook/Zalo app review) delayed — dev cannot test real channel integration | C5: External | D5: Medium | E5: High | F5: 6 | G5: Start approval process in Week 1; use mock/test accounts during development | H5: Continue with mock channels; adjust timeline for Iteration 2 | I5: PM | J5: Week 2 | K5: Open
A6: R-002 | B6: Key team member unavailable (illness, withdrawal) mid-project | C6: Resource | D6: Low | E6: High | F6: 3 | G6: Cross-train all members on critical modules; maintain shared knowledge base | H6: Reassign tasks; PM escalates to instructor if unresolvable | I6: PM | K6: Open
A7: R-003 | B7: Requirements change after SRS v1.0 is approved (scope creep) | C7: Scope | D7: Medium | E7: Medium | F7: 4 | G7: Strict change control: all changes go through ChangeLog; no mid-sprint changes | H7: Negotiate scope with PO; defer low-priority features to later iteration | I7: PM | K7: Open
A8: R-004 | B8: Integration with third-party API (payment/courier) fails in sandbox | C8: Technical | D8: Medium | E8: Medium | F8: 4 | G8: Implement WireMock stubs for all external API calls; test independently | H8: Use manual entry fallback; document limitation in final report | I8: Tech Lead | K8: Open
A9: R-005 | B9: Performance targets not met (slow response at peak load) | C9: Technical | D9: Low | E9: Medium | F9: 2 | G9: Performance testing starts Iteration 3; add DB indexes early | H9: Scope down concurrent user target; document as known limitation | I9: Tech Lead | J9: Week 10 | K9: Open
A10: R-006 | B10: UAT findings require significant rework, delaying go-live | C10: Quality | D10: Medium | E10: High | F10: 6 | G10: Involve PO in every Sprint Review; demo features every 2 weeks | H10: Prioritise P1 fixes; negotiate deferred fixes for post-go-live | I10: PM | J10: Week 13 | K10: Open
A11: R-007 | D11: Medium | E11: Medium | K11: Open
A12: R-008 | D12: Medium | E12: Medium | K12: Open
A13: R-009 | D13: Medium | E13: Medium | K13: Open
A14: R-010 | D14: Medium | E14: Medium | K14: Open
A15: R-011 | D15: Medium | E15: Medium | K15: Open
A16: R-012 | D16: Medium | E16: Medium | K16: Open
A17: R-013 | D17: Medium | E17: Medium | K17: Open
A18: R-014 | D18: Medium | E18: Medium | K18: Open
A19: R-015 | D19: Medium | E19: Medium | K19: Open

Sheet ChangeLog
A1: ChangeLog — Requirement & Scope Change Tracking
A2: Log ALL changes to requirements, design, or scope · No mid-sprint changes without approval · Reference this log when versions of SRS/SDS increment
A4: # | B4: Date | C4: Change Description | D4: Requested By | E4: Affects (SRS/WBS/Code) | F4: Impact on Scope | G4: Impact on Effort (pds) | H4: Impact on Timeline | I4: Priority | J4: Approved By | K4: Status | L4: Notes
A5: C-001 | B5: 2024-01-08 | C5: Add 'Forgot Password via OTP' feature to SRS — not in original scope | D5: KienNT | E5: SRS v1.0 Section 3, WBS #4 | F5: Add Reset Password screen (WBS #4) | G5: +3 pds | H5: Delay Iteration 1 by 3 days | I5: Medium | J5: [Approver] | K5: Pending | L5: Moved to Iteration 3 to reduce risk
A6: C-002 | I6: Medium | K6: Pending
A7: C-003 | I7: Medium | K7: Pending
A8: C-004 | I8: Medium | K8: Pending
A9: C-005 | I9: Medium | K9: Pending
A10: C-006 | I10: Medium | K10: Pending
A11: C-007 | I11: Medium | K11: Pending
A12: C-008 | I12: Medium | K12: Pending
A13: C-009 | I13: Medium | K13: Pending
A14: C-010 | I14: Medium | K14: Pending
A15: C-011 | I15: Medium | K15: Pending
A16: C-012 | I16: Medium | K16: Pending
A17: C-013 | I17: Medium | K17: Pending
... A24: C-020 | I24: Medium | K24: Pending
